[2025-02-06T12:51:40.253+0000] {local_task_job_runner.py:123} INFO - ::group::Pre task execution logs
[2025-02-06T12:51:40.271+0000] {taskinstance.py:2613} INFO - Dependencies all met for dep_context=non-requeueable deps ti=<TaskInstance: my_training_dag.task_insert_data_to_db manual__2025-02-06T12:51:21.979721+00:00 [queued]>
[2025-02-06T12:51:40.285+0000] {taskinstance.py:2613} INFO - Dependencies all met for dep_context=requeueable deps ti=<TaskInstance: my_training_dag.task_insert_data_to_db manual__2025-02-06T12:51:21.979721+00:00 [queued]>
[2025-02-06T12:51:40.287+0000] {taskinstance.py:2866} INFO - Starting attempt 1 of 1
[2025-02-06T12:51:40.327+0000] {taskinstance.py:2889} INFO - Executing <Task(PythonOperator): task_insert_data_to_db> on 2025-02-06 12:51:21.979721+00:00
[2025-02-06T12:51:40.333+0000] {standard_task_runner.py:72} INFO - Started process 14660 to run task
[2025-02-06T12:51:40.335+0000] {standard_task_runner.py:104} INFO - Running: ['airflow', 'tasks', 'run', 'my_training_dag', 'task_insert_data_to_db', 'manual__2025-02-06T12:51:21.979721+00:00', '--job-id', '2984', '--raw', '--subdir', 'DAGS_FOLDER/training_dag.py', '--cfg-path', '/tmp/tmpj3ly7osc']
[2025-02-06T12:51:40.336+0000] {standard_task_runner.py:105} INFO - Job 2984: Subtask task_insert_data_to_db
[2025-02-06T12:51:40.424+0000] {task_command.py:467} INFO - Running <TaskInstance: my_training_dag.task_insert_data_to_db manual__2025-02-06T12:51:21.979721+00:00 [running]> on host f59ce29465b4
[2025-02-06T12:51:40.513+0000] {taskinstance.py:3132} INFO - Exporting env vars: AIRFLOW_CTX_DAG_OWNER='airflow' AIRFLOW_CTX_DAG_ID='my_training_dag' AIRFLOW_CTX_TASK_ID='task_insert_data_to_db' AIRFLOW_CTX_EXECUTION_DATE='2025-02-06T12:51:21.979721+00:00' AIRFLOW_CTX_TRY_NUMBER='1' AIRFLOW_CTX_DAG_RUN_ID='manual__2025-02-06T12:51:21.979721+00:00'
[2025-02-06T12:51:40.515+0000] {logging_mixin.py:190} INFO - Task instance is in running state
[2025-02-06T12:51:40.516+0000] {logging_mixin.py:190} INFO -  Previous state of the Task instance: queued
[2025-02-06T12:51:40.517+0000] {logging_mixin.py:190} INFO - Current task name:task_insert_data_to_db state:running start_date:2025-02-06 12:51:40.272623+00:00
[2025-02-06T12:51:40.517+0000] {logging_mixin.py:190} INFO - Dag name:my_training_dag and current dag run status:running
[2025-02-06T12:51:40.518+0000] {taskinstance.py:731} INFO - ::endgroup::
[2025-02-06T12:51:40.532+0000] {logging_mixin.py:190} INFO - Table : 'iris_data'  created succesfully
[2025-02-06T12:51:40.545+0000] {taskinstance.py:3311} ERROR - Task failed with exception
Traceback (most recent call last):
  File "/opt/conda/lib/python3.12/site-packages/airflow/models/taskinstance.py", line 767, in _execute_task
    result = _execute_callable(context=context, **execute_callable_kwargs)
             ^^^^^^^^^^^^^^^^^^^^^^^^^^^^^^^^^^^^^^^^^^^^^^^^^^^^^^^^^^^^^
  File "/opt/conda/lib/python3.12/site-packages/airflow/models/taskinstance.py", line 733, in _execute_callable
    return ExecutionCallableRunner(
           ^^^^^^^^^^^^^^^^^^^^^^^^
  File "/opt/conda/lib/python3.12/site-packages/airflow/utils/operator_helpers.py", line 252, in run
    return self.func(*args, **kwargs)
           ^^^^^^^^^^^^^^^^^^^^^^^^^^
  File "/opt/conda/lib/python3.12/site-packages/airflow/models/baseoperator.py", line 422, in wrapper
    return func(self, *args, **kwargs)
           ^^^^^^^^^^^^^^^^^^^^^^^^^^^
  File "/opt/conda/lib/python3.12/site-packages/airflow/operators/python.py", line 238, in execute
    return_value = self.execute_callable()
                   ^^^^^^^^^^^^^^^^^^^^^^^
  File "/opt/conda/lib/python3.12/site-packages/airflow/operators/python.py", line 256, in execute_callable
    return runner.run(*self.op_args, **self.op_kwargs)
           ^^^^^^^^^^^^^^^^^^^^^^^^^^^^^^^^^^^^^^^^^^^
  File "/opt/conda/lib/python3.12/site-packages/airflow/utils/operator_helpers.py", line 252, in run
    return self.func(*args, **kwargs)
           ^^^^^^^^^^^^^^^^^^^^^^^^^^
  File "/root/airflow/dags/training_dag.py", line 29, in insert_data_to_db
    data_value = df.iloc[n]
                 ^^
NameError: name 'df' is not defined
[2025-02-06T12:51:40.560+0000] {logging_mixin.py:190} INFO - Task instance in failure state
[2025-02-06T12:51:40.561+0000] {logging_mixin.py:190} INFO - Task start:2025-02-06 12:51:40.272623+00:00 end:2025-02-06 12:51:40.560293+00:00 duration:0.28767
[2025-02-06T12:51:40.561+0000] {logging_mixin.py:190} INFO - Task:<Task(PythonOperator): task_insert_data_to_db> dag:<DAG: my_training_dag> dagrun:<DagRun my_training_dag @ 2025-02-06 12:51:21.979721+00:00: manual__2025-02-06T12:51:21.979721+00:00, state:running, queued_at: 2025-02-06 12:51:22.023057+00:00. externally triggered: True>
[2025-02-06T12:51:40.562+0000] {logging_mixin.py:190} INFO - Failure caused by name 'df' is not defined
[2025-02-06T12:51:40.562+0000] {taskinstance.py:1225} INFO - Marking task as FAILED. dag_id=my_training_dag, task_id=task_insert_data_to_db, run_id=manual__2025-02-06T12:51:21.979721+00:00, execution_date=20250206T125121, start_date=20250206T125140, end_date=20250206T125140
[2025-02-06T12:51:40.607+0000] {taskinstance.py:340} INFO - ::group::Post task execution logs
[2025-02-06T12:51:40.609+0000] {standard_task_runner.py:124} ERROR - Failed to execute job 2984 for task task_insert_data_to_db (name 'df' is not defined; 14660)
Traceback (most recent call last):
  File "/opt/conda/lib/python3.12/site-packages/airflow/task/task_runner/standard_task_runner.py", line 117, in _start_by_fork
    ret = args.func(args, dag=self.dag)
          ^^^^^^^^^^^^^^^^^^^^^^^^^^^^^
  File "/opt/conda/lib/python3.12/site-packages/airflow/cli/cli_config.py", line 49, in command
    return func(*args, **kwargs)
           ^^^^^^^^^^^^^^^^^^^^^
  File "/opt/conda/lib/python3.12/site-packages/airflow/utils/cli.py", line 116, in wrapper
    return f(*args, **kwargs)
           ^^^^^^^^^^^^^^^^^^
  File "/opt/conda/lib/python3.12/site-packages/airflow/cli/commands/task_command.py", line 483, in task_run
    task_return_code = _run_task_by_selected_method(args, _dag, ti)
                       ^^^^^^^^^^^^^^^^^^^^^^^^^^^^^^^^^^^^^^^^^^^^
  File "/opt/conda/lib/python3.12/site-packages/airflow/cli/commands/task_command.py", line 256, in _run_task_by_selected_method
    return _run_raw_task(args, ti)
           ^^^^^^^^^^^^^^^^^^^^^^^
  File "/opt/conda/lib/python3.12/site-packages/airflow/cli/commands/task_command.py", line 341, in _run_raw_task
    return ti._run_raw_task(
           ^^^^^^^^^^^^^^^^^
  File "/opt/conda/lib/python3.12/site-packages/airflow/utils/session.py", line 97, in wrapper
    return func(*args, session=session, **kwargs)
           ^^^^^^^^^^^^^^^^^^^^^^^^^^^^^^^^^^^^^^
  File "/opt/conda/lib/python3.12/site-packages/airflow/models/taskinstance.py", line 3005, in _run_raw_task
    return _run_raw_task(
           ^^^^^^^^^^^^^^
  File "/opt/conda/lib/python3.12/site-packages/airflow/models/taskinstance.py", line 273, in _run_raw_task
    TaskInstance._execute_task_with_callbacks(
  File "/opt/conda/lib/python3.12/site-packages/airflow/models/taskinstance.py", line 3159, in _execute_task_with_callbacks
    result = self._execute_task(context, task_orig)
             ^^^^^^^^^^^^^^^^^^^^^^^^^^^^^^^^^^^^^^
  File "/opt/conda/lib/python3.12/site-packages/airflow/models/taskinstance.py", line 3183, in _execute_task
    return _execute_task(self, context, task_orig)
           ^^^^^^^^^^^^^^^^^^^^^^^^^^^^^^^^^^^^^^^
  File "/opt/conda/lib/python3.12/site-packages/airflow/models/taskinstance.py", line 767, in _execute_task
    result = _execute_callable(context=context, **execute_callable_kwargs)
             ^^^^^^^^^^^^^^^^^^^^^^^^^^^^^^^^^^^^^^^^^^^^^^^^^^^^^^^^^^^^^
  File "/opt/conda/lib/python3.12/site-packages/airflow/models/taskinstance.py", line 733, in _execute_callable
    return ExecutionCallableRunner(
           ^^^^^^^^^^^^^^^^^^^^^^^^
  File "/opt/conda/lib/python3.12/site-packages/airflow/utils/operator_helpers.py", line 252, in run
    return self.func(*args, **kwargs)
           ^^^^^^^^^^^^^^^^^^^^^^^^^^
  File "/opt/conda/lib/python3.12/site-packages/airflow/models/baseoperator.py", line 422, in wrapper
    return func(self, *args, **kwargs)
           ^^^^^^^^^^^^^^^^^^^^^^^^^^^
  File "/opt/conda/lib/python3.12/site-packages/airflow/operators/python.py", line 238, in execute
    return_value = self.execute_callable()
                   ^^^^^^^^^^^^^^^^^^^^^^^
  File "/opt/conda/lib/python3.12/site-packages/airflow/operators/python.py", line 256, in execute_callable
    return runner.run(*self.op_args, **self.op_kwargs)
           ^^^^^^^^^^^^^^^^^^^^^^^^^^^^^^^^^^^^^^^^^^^
  File "/opt/conda/lib/python3.12/site-packages/airflow/utils/operator_helpers.py", line 252, in run
    return self.func(*args, **kwargs)
           ^^^^^^^^^^^^^^^^^^^^^^^^^^
  File "/root/airflow/dags/training_dag.py", line 29, in insert_data_to_db
    data_value = df.iloc[n]
                 ^^
NameError: name 'df' is not defined
[2025-02-06T12:51:40.631+0000] {local_task_job_runner.py:266} INFO - Task exited with return code 1
[2025-02-06T12:51:40.657+0000] {taskinstance.py:3895} INFO - 0 downstream tasks scheduled from follow-on schedule check
[2025-02-06T12:51:40.659+0000] {local_task_job_runner.py:245} INFO - ::endgroup::
