[2025-02-06T13:31:37.590+0000] {local_task_job_runner.py:123} INFO - ::group::Pre task execution logs
[2025-02-06T13:31:37.624+0000] {taskinstance.py:2613} INFO - Dependencies all met for dep_context=non-requeueable deps ti=<TaskInstance: my_first_dag.task_random_choice scheduled__2025-01-01T07:52:00+00:00 [queued]>
[2025-02-06T13:31:37.668+0000] {taskinstance.py:2613} INFO - Dependencies all met for dep_context=requeueable deps ti=<TaskInstance: my_first_dag.task_random_choice scheduled__2025-01-01T07:52:00+00:00 [queued]>
[2025-02-06T13:31:37.669+0000] {taskinstance.py:2866} INFO - Starting attempt 1 of 1
[2025-02-06T13:31:37.892+0000] {taskinstance.py:2889} INFO - Executing <Task(BranchPythonOperator): task_random_choice> on 2025-01-01 07:52:00+00:00
[2025-02-06T13:31:37.900+0000] {standard_task_runner.py:72} INFO - Started process 5386 to run task
[2025-02-06T13:31:37.902+0000] {standard_task_runner.py:104} INFO - Running: ['airflow', 'tasks', 'run', 'my_first_dag', 'task_random_choice', 'scheduled__2025-01-01T07:52:00+00:00', '--job-id', '3335', '--raw', '--subdir', 'DAGS_FOLDER/first_dag.py', '--cfg-path', '/tmp/tmp3wldtkmv']
[2025-02-06T13:31:37.903+0000] {standard_task_runner.py:105} INFO - Job 3335: Subtask task_random_choice
[2025-02-06T13:31:38.027+0000] {task_command.py:467} INFO - Running <TaskInstance: my_first_dag.task_random_choice scheduled__2025-01-01T07:52:00+00:00 [running]> on host cbb1459a86bc
[2025-02-06T13:31:38.185+0000] {taskinstance.py:3132} INFO - Exporting env vars: AIRFLOW_CTX_DAG_OWNER='airflow' AIRFLOW_CTX_DAG_ID='my_first_dag' AIRFLOW_CTX_TASK_ID='task_random_choice' AIRFLOW_CTX_EXECUTION_DATE='2025-01-01T07:52:00+00:00' AIRFLOW_CTX_TRY_NUMBER='1' AIRFLOW_CTX_DAG_RUN_ID='scheduled__2025-01-01T07:52:00+00:00'
[2025-02-06T13:31:38.186+0000] {logging_mixin.py:190} INFO - Task instance is in running state
[2025-02-06T13:31:38.187+0000] {logging_mixin.py:190} INFO -  Previous state of the Task instance: queued
[2025-02-06T13:31:38.187+0000] {logging_mixin.py:190} INFO - Current task name:task_random_choice state:running start_date:2025-02-06 13:31:37.625436+00:00
[2025-02-06T13:31:38.188+0000] {logging_mixin.py:190} INFO - Dag name:my_first_dag and current dag run status:running
[2025-02-06T13:31:38.188+0000] {taskinstance.py:731} INFO - ::endgroup::
[2025-02-06T13:31:38.189+0000] {baseoperator.py:421} WARNING - BranchPythonOperator.execute cannot be called outside TaskInstance!
[2025-02-06T13:31:38.190+0000] {python.py:240} INFO - Done. Returned value was: task_2
[2025-02-06T13:31:38.190+0000] {branch.py:38} INFO - Branch into task_2
[2025-02-06T13:31:38.192+0000] {skipmixin.py:230} INFO - Following branch ('task_2',)
[2025-02-06T13:31:38.211+0000] {skipmixin.py:278} INFO - Skipping tasks [('task_1', -1)]
[2025-02-06T13:31:38.283+0000] {taskinstance.py:3311} ERROR - Task failed with exception
Traceback (most recent call last):
  File "/opt/conda/lib/python3.12/site-packages/sqlalchemy/engine/base.py", line 1094, in _commit_impl
    self.engine.dialect.do_commit(self.connection)
  File "/opt/conda/lib/python3.12/site-packages/sqlalchemy/engine/default.py", line 686, in do_commit
    dbapi_connection.commit()
sqlite3.OperationalError: disk I/O error

The above exception was the direct cause of the following exception:

Traceback (most recent call last):
  File "/opt/conda/lib/python3.12/site-packages/airflow/models/taskinstance.py", line 767, in _execute_task
    result = _execute_callable(context=context, **execute_callable_kwargs)
             ^^^^^^^^^^^^^^^^^^^^^^^^^^^^^^^^^^^^^^^^^^^^^^^^^^^^^^^^^^^^^
  File "/opt/conda/lib/python3.12/site-packages/airflow/models/taskinstance.py", line 733, in _execute_callable
    return ExecutionCallableRunner(
           ^^^^^^^^^^^^^^^^^^^^^^^^
  File "/opt/conda/lib/python3.12/site-packages/airflow/utils/operator_helpers.py", line 252, in run
    return self.func(*args, **kwargs)
           ^^^^^^^^^^^^^^^^^^^^^^^^^^
  File "/opt/conda/lib/python3.12/site-packages/airflow/models/baseoperator.py", line 422, in wrapper
    return func(self, *args, **kwargs)
           ^^^^^^^^^^^^^^^^^^^^^^^^^^^
  File "/opt/conda/lib/python3.12/site-packages/airflow/operators/python.py", line 274, in execute
    return self.do_branch(context, super().execute(context))
           ^^^^^^^^^^^^^^^^^^^^^^^^^^^^^^^^^^^^^^^^^^^^^^^^^
  File "/opt/conda/lib/python3.12/site-packages/airflow/operators/branch.py", line 40, in do_branch
    self.skip_all_except(context["ti"], branch_task_ids)
  File "/opt/conda/lib/python3.12/site-packages/airflow/models/skipmixin.py", line 189, in skip_all_except
    SkipMixin._skip_all_except(ti=ti, branch_task_ids=branch_task_ids)
  File "/opt/conda/lib/python3.12/site-packages/airflow/api_internal/internal_api_call.py", line 166, in wrapper
    return func(*args, **kwargs)
           ^^^^^^^^^^^^^^^^^^^^^
  File "/opt/conda/lib/python3.12/site-packages/airflow/utils/session.py", line 96, in wrapper
    with create_session() as session:
         ^^^^^^^^^^^^^^^^
  File "/opt/conda/lib/python3.12/contextlib.py", line 144, in __exit__
    next(self.gen)
  File "/opt/conda/lib/python3.12/site-packages/airflow/utils/session.py", line 57, in create_session
    session.commit()
  File "/opt/conda/lib/python3.12/site-packages/sqlalchemy/orm/session.py", line 1454, in commit
    self._transaction.commit(_to_root=self.future)
  File "/opt/conda/lib/python3.12/site-packages/sqlalchemy/orm/session.py", line 839, in commit
    trans.commit()
  File "/opt/conda/lib/python3.12/site-packages/sqlalchemy/engine/base.py", line 2469, in commit
    self._do_commit()
  File "/opt/conda/lib/python3.12/site-packages/sqlalchemy/engine/base.py", line 2659, in _do_commit
    self._connection_commit_impl()
  File "/opt/conda/lib/python3.12/site-packages/sqlalchemy/engine/base.py", line 2630, in _connection_commit_impl
    self.connection._commit_impl()
  File "/opt/conda/lib/python3.12/site-packages/sqlalchemy/engine/base.py", line 1096, in _commit_impl
    self._handle_dbapi_exception(e, None, None, None, None)
  File "/opt/conda/lib/python3.12/site-packages/sqlalchemy/engine/base.py", line 2134, in _handle_dbapi_exception
    util.raise_(
  File "/opt/conda/lib/python3.12/site-packages/sqlalchemy/util/compat.py", line 211, in raise_
    raise exception
  File "/opt/conda/lib/python3.12/site-packages/sqlalchemy/engine/base.py", line 1094, in _commit_impl
    self.engine.dialect.do_commit(self.connection)
  File "/opt/conda/lib/python3.12/site-packages/sqlalchemy/engine/default.py", line 686, in do_commit
    dbapi_connection.commit()
sqlalchemy.exc.OperationalError: (sqlite3.OperationalError) disk I/O error
(Background on this error at: https://sqlalche.me/e/14/e3q8)
[2025-02-06T13:31:38.353+0000] {logging_mixin.py:190} INFO - Task instance in failure state
[2025-02-06T13:31:38.354+0000] {logging_mixin.py:190} INFO - Task start:2025-02-06 13:31:37.625436+00:00 end:2025-02-06 13:31:38.352071+00:00 duration:0.726635
[2025-02-06T13:31:38.355+0000] {logging_mixin.py:190} INFO - Task:<Task(BranchPythonOperator): task_random_choice> dag:<DAG: my_first_dag> dagrun:<DagRun my_first_dag @ 2025-01-01 07:52:00+00:00: scheduled__2025-01-01T07:52:00+00:00, state:running, queued_at: 2025-02-06 13:31:28.255708+00:00. externally triggered: False>
[2025-02-06T13:31:38.356+0000] {logging_mixin.py:190} INFO - Failure caused by (sqlite3.OperationalError) disk I/O error
(Background on this error at: https://sqlalche.me/e/14/e3q8)
[2025-02-06T13:31:38.357+0000] {taskinstance.py:1225} INFO - Marking task as FAILED. dag_id=my_first_dag, task_id=task_random_choice, run_id=scheduled__2025-01-01T07:52:00+00:00, execution_date=20250101T075200, start_date=20250206T133137, end_date=20250206T133138
[2025-02-06T13:31:38.420+0000] {taskinstance.py:340} INFO - ::group::Post task execution logs
[2025-02-06T13:31:38.421+0000] {standard_task_runner.py:124} ERROR - Failed to execute job 3335 for task task_random_choice ((sqlite3.OperationalError) disk I/O error
(Background on this error at: https://sqlalche.me/e/14/e3q8); 5386)
Traceback (most recent call last):
  File "/opt/conda/lib/python3.12/site-packages/sqlalchemy/engine/base.py", line 1094, in _commit_impl
    self.engine.dialect.do_commit(self.connection)
  File "/opt/conda/lib/python3.12/site-packages/sqlalchemy/engine/default.py", line 686, in do_commit
    dbapi_connection.commit()
sqlite3.OperationalError: disk I/O error

The above exception was the direct cause of the following exception:

Traceback (most recent call last):
  File "/opt/conda/lib/python3.12/site-packages/airflow/task/task_runner/standard_task_runner.py", line 117, in _start_by_fork
    ret = args.func(args, dag=self.dag)
          ^^^^^^^^^^^^^^^^^^^^^^^^^^^^^
  File "/opt/conda/lib/python3.12/site-packages/airflow/cli/cli_config.py", line 49, in command
    return func(*args, **kwargs)
           ^^^^^^^^^^^^^^^^^^^^^
  File "/opt/conda/lib/python3.12/site-packages/airflow/utils/cli.py", line 116, in wrapper
    return f(*args, **kwargs)
           ^^^^^^^^^^^^^^^^^^
  File "/opt/conda/lib/python3.12/site-packages/airflow/cli/commands/task_command.py", line 483, in task_run
    task_return_code = _run_task_by_selected_method(args, _dag, ti)
                       ^^^^^^^^^^^^^^^^^^^^^^^^^^^^^^^^^^^^^^^^^^^^
  File "/opt/conda/lib/python3.12/site-packages/airflow/cli/commands/task_command.py", line 256, in _run_task_by_selected_method
    return _run_raw_task(args, ti)
           ^^^^^^^^^^^^^^^^^^^^^^^
  File "/opt/conda/lib/python3.12/site-packages/airflow/cli/commands/task_command.py", line 341, in _run_raw_task
    return ti._run_raw_task(
           ^^^^^^^^^^^^^^^^^
  File "/opt/conda/lib/python3.12/site-packages/airflow/utils/session.py", line 97, in wrapper
    return func(*args, session=session, **kwargs)
           ^^^^^^^^^^^^^^^^^^^^^^^^^^^^^^^^^^^^^^
  File "/opt/conda/lib/python3.12/site-packages/airflow/models/taskinstance.py", line 3005, in _run_raw_task
    return _run_raw_task(
           ^^^^^^^^^^^^^^
  File "/opt/conda/lib/python3.12/site-packages/airflow/models/taskinstance.py", line 273, in _run_raw_task
    TaskInstance._execute_task_with_callbacks(
  File "/opt/conda/lib/python3.12/site-packages/airflow/models/taskinstance.py", line 3159, in _execute_task_with_callbacks
    result = self._execute_task(context, task_orig)
             ^^^^^^^^^^^^^^^^^^^^^^^^^^^^^^^^^^^^^^
  File "/opt/conda/lib/python3.12/site-packages/airflow/models/taskinstance.py", line 3183, in _execute_task
    return _execute_task(self, context, task_orig)
           ^^^^^^^^^^^^^^^^^^^^^^^^^^^^^^^^^^^^^^^
  File "/opt/conda/lib/python3.12/site-packages/airflow/models/taskinstance.py", line 767, in _execute_task
    result = _execute_callable(context=context, **execute_callable_kwargs)
             ^^^^^^^^^^^^^^^^^^^^^^^^^^^^^^^^^^^^^^^^^^^^^^^^^^^^^^^^^^^^^
  File "/opt/conda/lib/python3.12/site-packages/airflow/models/taskinstance.py", line 733, in _execute_callable
    return ExecutionCallableRunner(
           ^^^^^^^^^^^^^^^^^^^^^^^^
  File "/opt/conda/lib/python3.12/site-packages/airflow/utils/operator_helpers.py", line 252, in run
    return self.func(*args, **kwargs)
           ^^^^^^^^^^^^^^^^^^^^^^^^^^
  File "/opt/conda/lib/python3.12/site-packages/airflow/models/baseoperator.py", line 422, in wrapper
    return func(self, *args, **kwargs)
           ^^^^^^^^^^^^^^^^^^^^^^^^^^^
  File "/opt/conda/lib/python3.12/site-packages/airflow/operators/python.py", line 274, in execute
    return self.do_branch(context, super().execute(context))
           ^^^^^^^^^^^^^^^^^^^^^^^^^^^^^^^^^^^^^^^^^^^^^^^^^
  File "/opt/conda/lib/python3.12/site-packages/airflow/operators/branch.py", line 40, in do_branch
    self.skip_all_except(context["ti"], branch_task_ids)
  File "/opt/conda/lib/python3.12/site-packages/airflow/models/skipmixin.py", line 189, in skip_all_except
    SkipMixin._skip_all_except(ti=ti, branch_task_ids=branch_task_ids)
  File "/opt/conda/lib/python3.12/site-packages/airflow/api_internal/internal_api_call.py", line 166, in wrapper
    return func(*args, **kwargs)
           ^^^^^^^^^^^^^^^^^^^^^
  File "/opt/conda/lib/python3.12/site-packages/airflow/utils/session.py", line 96, in wrapper
    with create_session() as session:
         ^^^^^^^^^^^^^^^^
  File "/opt/conda/lib/python3.12/contextlib.py", line 144, in __exit__
    next(self.gen)
  File "/opt/conda/lib/python3.12/site-packages/airflow/utils/session.py", line 57, in create_session
    session.commit()
  File "/opt/conda/lib/python3.12/site-packages/sqlalchemy/orm/session.py", line 1454, in commit
    self._transaction.commit(_to_root=self.future)
  File "/opt/conda/lib/python3.12/site-packages/sqlalchemy/orm/session.py", line 839, in commit
    trans.commit()
  File "/opt/conda/lib/python3.12/site-packages/sqlalchemy/engine/base.py", line 2469, in commit
    self._do_commit()
  File "/opt/conda/lib/python3.12/site-packages/sqlalchemy/engine/base.py", line 2659, in _do_commit
    self._connection_commit_impl()
  File "/opt/conda/lib/python3.12/site-packages/sqlalchemy/engine/base.py", line 2630, in _connection_commit_impl
    self.connection._commit_impl()
  File "/opt/conda/lib/python3.12/site-packages/sqlalchemy/engine/base.py", line 1096, in _commit_impl
    self._handle_dbapi_exception(e, None, None, None, None)
  File "/opt/conda/lib/python3.12/site-packages/sqlalchemy/engine/base.py", line 2134, in _handle_dbapi_exception
    util.raise_(
  File "/opt/conda/lib/python3.12/site-packages/sqlalchemy/util/compat.py", line 211, in raise_
    raise exception
  File "/opt/conda/lib/python3.12/site-packages/sqlalchemy/engine/base.py", line 1094, in _commit_impl
    self.engine.dialect.do_commit(self.connection)
  File "/opt/conda/lib/python3.12/site-packages/sqlalchemy/engine/default.py", line 686, in do_commit
    dbapi_connection.commit()
sqlalchemy.exc.OperationalError: (sqlite3.OperationalError) disk I/O error
(Background on this error at: https://sqlalche.me/e/14/e3q8)
[2025-02-06T13:31:38.438+0000] {local_task_job_runner.py:266} INFO - Task exited with return code 1
[2025-02-06T13:31:38.488+0000] {taskinstance.py:3895} INFO - 0 downstream tasks scheduled from follow-on schedule check
[2025-02-06T13:31:38.513+0000] {local_task_job_runner.py:245} INFO - ::endgroup::
