[2025-02-06T11:41:28.261+0000] {local_task_job_runner.py:123} INFO - ::group::Pre task execution logs
[2025-02-06T11:41:28.288+0000] {taskinstance.py:2613} INFO - Dependencies all met for dep_context=non-requeueable deps ti=<TaskInstance: my_first_dag.task_1 scheduled__2025-01-01T06:17:00+00:00 [queued]>
[2025-02-06T11:41:28.318+0000] {taskinstance.py:2613} INFO - Dependencies all met for dep_context=requeueable deps ti=<TaskInstance: my_first_dag.task_1 scheduled__2025-01-01T06:17:00+00:00 [queued]>
[2025-02-06T11:41:28.319+0000] {taskinstance.py:2866} INFO - Starting attempt 1 of 1
[2025-02-06T11:41:28.496+0000] {taskinstance.py:2889} INFO - Executing <Task(PythonOperator): task_1> on 2025-01-01 06:17:00+00:00
[2025-02-06T11:41:28.503+0000] {standard_task_runner.py:72} INFO - Started process 640 to run task
[2025-02-06T11:41:28.505+0000] {standard_task_runner.py:104} INFO - Running: ['airflow', 'tasks', 'run', 'my_first_dag', 'task_1', 'scheduled__2025-01-01T06:17:00+00:00', '--job-id', '2087', '--raw', '--subdir', 'DAGS_FOLDER/first_dag.py', '--cfg-path', '/tmp/tmpr06u0soe']
[2025-02-06T11:41:28.506+0000] {standard_task_runner.py:105} INFO - Job 2087: Subtask task_1
[2025-02-06T11:41:28.611+0000] {task_command.py:467} INFO - Running <TaskInstance: my_first_dag.task_1 scheduled__2025-01-01T06:17:00+00:00 [running]> on host 7e1f175e93b1
[2025-02-06T11:41:28.743+0000] {taskinstance.py:3132} INFO - Exporting env vars: AIRFLOW_CTX_DAG_OWNER='airflow' AIRFLOW_CTX_DAG_ID='my_first_dag' AIRFLOW_CTX_TASK_ID='task_1' AIRFLOW_CTX_EXECUTION_DATE='2025-01-01T06:17:00+00:00' AIRFLOW_CTX_TRY_NUMBER='1' AIRFLOW_CTX_DAG_RUN_ID='scheduled__2025-01-01T06:17:00+00:00'
[2025-02-06T11:41:28.745+0000] {logging_mixin.py:190} INFO - Task instance is in running state
[2025-02-06T11:41:28.746+0000] {logging_mixin.py:190} INFO -  Previous state of the Task instance: queued
[2025-02-06T11:41:28.747+0000] {logging_mixin.py:190} INFO - Current task name:task_1 state:running start_date:2025-02-06 11:41:28.289295+00:00
[2025-02-06T11:41:28.747+0000] {logging_mixin.py:190} INFO - Dag name:my_first_dag and current dag run status:running
[2025-02-06T11:41:28.748+0000] {taskinstance.py:731} INFO - ::endgroup::
[2025-02-06T11:41:28.773+0000] {logging_mixin.py:190} INFO - Hello Kevin 634 API_KEY
[2025-02-06T11:41:28.774+0000] {python.py:240} INFO - Done. Returned value was: 634
[2025-02-06T11:41:28.822+0000] {taskinstance.py:3311} ERROR - Task failed with exception
Traceback (most recent call last):
  File "/opt/conda/lib/python3.12/site-packages/sqlalchemy/engine/base.py", line 1094, in _commit_impl
    self.engine.dialect.do_commit(self.connection)
  File "/opt/conda/lib/python3.12/site-packages/sqlalchemy/engine/default.py", line 686, in do_commit
    dbapi_connection.commit()
sqlite3.OperationalError: disk I/O error

The above exception was the direct cause of the following exception:

Traceback (most recent call last):
  File "/opt/conda/lib/python3.12/site-packages/airflow/models/taskinstance.py", line 769, in _execute_task
    with cm as session_or_null:
         ^^
  File "/opt/conda/lib/python3.12/contextlib.py", line 144, in __exit__
    next(self.gen)
  File "/opt/conda/lib/python3.12/site-packages/airflow/utils/session.py", line 57, in create_session
    session.commit()
  File "/opt/conda/lib/python3.12/site-packages/sqlalchemy/orm/session.py", line 1454, in commit
    self._transaction.commit(_to_root=self.future)
  File "/opt/conda/lib/python3.12/site-packages/sqlalchemy/orm/session.py", line 839, in commit
    trans.commit()
  File "/opt/conda/lib/python3.12/site-packages/sqlalchemy/engine/base.py", line 2469, in commit
    self._do_commit()
  File "/opt/conda/lib/python3.12/site-packages/sqlalchemy/engine/base.py", line 2659, in _do_commit
    self._connection_commit_impl()
  File "/opt/conda/lib/python3.12/site-packages/sqlalchemy/engine/base.py", line 2630, in _connection_commit_impl
    self.connection._commit_impl()
  File "/opt/conda/lib/python3.12/site-packages/sqlalchemy/engine/base.py", line 1096, in _commit_impl
    self._handle_dbapi_exception(e, None, None, None, None)
  File "/opt/conda/lib/python3.12/site-packages/sqlalchemy/engine/base.py", line 2134, in _handle_dbapi_exception
    util.raise_(
  File "/opt/conda/lib/python3.12/site-packages/sqlalchemy/util/compat.py", line 211, in raise_
    raise exception
  File "/opt/conda/lib/python3.12/site-packages/sqlalchemy/engine/base.py", line 1094, in _commit_impl
    self.engine.dialect.do_commit(self.connection)
  File "/opt/conda/lib/python3.12/site-packages/sqlalchemy/engine/default.py", line 686, in do_commit
    dbapi_connection.commit()
sqlalchemy.exc.OperationalError: (sqlite3.OperationalError) disk I/O error
(Background on this error at: https://sqlalche.me/e/14/e3q8)
[2025-02-06T11:41:28.966+0000] {logging_mixin.py:190} INFO - Task instance in failure state
[2025-02-06T11:41:28.966+0000] {logging_mixin.py:190} INFO - Task start:2025-02-06 11:41:28.289295+00:00 end:2025-02-06 11:41:28.965805+00:00 duration:0.67651
[2025-02-06T11:41:28.967+0000] {logging_mixin.py:190} INFO - Task:<Task(PythonOperator): task_1> dag:<DAG: my_first_dag> dagrun:<DagRun my_first_dag @ 2025-01-01 06:17:00+00:00: scheduled__2025-01-01T06:17:00+00:00, state:running, queued_at: 2025-02-06 11:41:13.821168+00:00. externally triggered: False>
[2025-02-06T11:41:28.968+0000] {logging_mixin.py:190} INFO - Failure caused by (sqlite3.OperationalError) disk I/O error
(Background on this error at: https://sqlalche.me/e/14/e3q8)
[2025-02-06T11:41:28.968+0000] {taskinstance.py:1225} INFO - Marking task as FAILED. dag_id=my_first_dag, task_id=task_1, run_id=scheduled__2025-01-01T06:17:00+00:00, execution_date=20250101T061700, start_date=20250206T114128, end_date=20250206T114128
[2025-02-06T11:41:29.002+0000] {taskinstance.py:340} INFO - ::group::Post task execution logs
[2025-02-06T11:41:29.003+0000] {standard_task_runner.py:124} ERROR - Failed to execute job 2087 for task task_1 ((sqlite3.OperationalError) disk I/O error
(Background on this error at: https://sqlalche.me/e/14/e3q8); 640)
Traceback (most recent call last):
  File "/opt/conda/lib/python3.12/site-packages/sqlalchemy/engine/base.py", line 1094, in _commit_impl
    self.engine.dialect.do_commit(self.connection)
  File "/opt/conda/lib/python3.12/site-packages/sqlalchemy/engine/default.py", line 686, in do_commit
    dbapi_connection.commit()
sqlite3.OperationalError: disk I/O error

The above exception was the direct cause of the following exception:

Traceback (most recent call last):
  File "/opt/conda/lib/python3.12/site-packages/airflow/task/task_runner/standard_task_runner.py", line 117, in _start_by_fork
    ret = args.func(args, dag=self.dag)
          ^^^^^^^^^^^^^^^^^^^^^^^^^^^^^
  File "/opt/conda/lib/python3.12/site-packages/airflow/cli/cli_config.py", line 49, in command
    return func(*args, **kwargs)
           ^^^^^^^^^^^^^^^^^^^^^
  File "/opt/conda/lib/python3.12/site-packages/airflow/utils/cli.py", line 116, in wrapper
    return f(*args, **kwargs)
           ^^^^^^^^^^^^^^^^^^
  File "/opt/conda/lib/python3.12/site-packages/airflow/cli/commands/task_command.py", line 483, in task_run
    task_return_code = _run_task_by_selected_method(args, _dag, ti)
                       ^^^^^^^^^^^^^^^^^^^^^^^^^^^^^^^^^^^^^^^^^^^^
  File "/opt/conda/lib/python3.12/site-packages/airflow/cli/commands/task_command.py", line 256, in _run_task_by_selected_method
    return _run_raw_task(args, ti)
           ^^^^^^^^^^^^^^^^^^^^^^^
  File "/opt/conda/lib/python3.12/site-packages/airflow/cli/commands/task_command.py", line 341, in _run_raw_task
    return ti._run_raw_task(
           ^^^^^^^^^^^^^^^^^
  File "/opt/conda/lib/python3.12/site-packages/airflow/utils/session.py", line 97, in wrapper
    return func(*args, session=session, **kwargs)
           ^^^^^^^^^^^^^^^^^^^^^^^^^^^^^^^^^^^^^^
  File "/opt/conda/lib/python3.12/site-packages/airflow/models/taskinstance.py", line 3005, in _run_raw_task
    return _run_raw_task(
           ^^^^^^^^^^^^^^
  File "/opt/conda/lib/python3.12/site-packages/airflow/models/taskinstance.py", line 273, in _run_raw_task
    TaskInstance._execute_task_with_callbacks(
  File "/opt/conda/lib/python3.12/site-packages/airflow/models/taskinstance.py", line 3159, in _execute_task_with_callbacks
    result = self._execute_task(context, task_orig)
             ^^^^^^^^^^^^^^^^^^^^^^^^^^^^^^^^^^^^^^
  File "/opt/conda/lib/python3.12/site-packages/airflow/models/taskinstance.py", line 3183, in _execute_task
    return _execute_task(self, context, task_orig)
           ^^^^^^^^^^^^^^^^^^^^^^^^^^^^^^^^^^^^^^^
  File "/opt/conda/lib/python3.12/site-packages/airflow/models/taskinstance.py", line 769, in _execute_task
    with cm as session_or_null:
         ^^
  File "/opt/conda/lib/python3.12/contextlib.py", line 144, in __exit__
    next(self.gen)
  File "/opt/conda/lib/python3.12/site-packages/airflow/utils/session.py", line 57, in create_session
    session.commit()
  File "/opt/conda/lib/python3.12/site-packages/sqlalchemy/orm/session.py", line 1454, in commit
    self._transaction.commit(_to_root=self.future)
  File "/opt/conda/lib/python3.12/site-packages/sqlalchemy/orm/session.py", line 839, in commit
    trans.commit()
  File "/opt/conda/lib/python3.12/site-packages/sqlalchemy/engine/base.py", line 2469, in commit
    self._do_commit()
  File "/opt/conda/lib/python3.12/site-packages/sqlalchemy/engine/base.py", line 2659, in _do_commit
    self._connection_commit_impl()
  File "/opt/conda/lib/python3.12/site-packages/sqlalchemy/engine/base.py", line 2630, in _connection_commit_impl
    self.connection._commit_impl()
  File "/opt/conda/lib/python3.12/site-packages/sqlalchemy/engine/base.py", line 1096, in _commit_impl
    self._handle_dbapi_exception(e, None, None, None, None)
  File "/opt/conda/lib/python3.12/site-packages/sqlalchemy/engine/base.py", line 2134, in _handle_dbapi_exception
    util.raise_(
  File "/opt/conda/lib/python3.12/site-packages/sqlalchemy/util/compat.py", line 211, in raise_
    raise exception
  File "/opt/conda/lib/python3.12/site-packages/sqlalchemy/engine/base.py", line 1094, in _commit_impl
    self.engine.dialect.do_commit(self.connection)
  File "/opt/conda/lib/python3.12/site-packages/sqlalchemy/engine/default.py", line 686, in do_commit
    dbapi_connection.commit()
sqlalchemy.exc.OperationalError: (sqlite3.OperationalError) disk I/O error
(Background on this error at: https://sqlalche.me/e/14/e3q8)
[2025-02-06T11:41:29.040+0000] {local_task_job_runner.py:266} INFO - Task exited with return code 1
[2025-02-06T11:41:29.072+0000] {taskinstance.py:3895} INFO - 0 downstream tasks scheduled from follow-on schedule check
[2025-02-06T11:41:29.099+0000] {local_task_job_runner.py:245} INFO - ::endgroup::
