[2025-02-06T12:23:24.262+0000] {local_task_job_runner.py:123} INFO - ::group::Pre task execution logs
[2025-02-06T12:23:24.317+0000] {taskinstance.py:2613} INFO - Dependencies all met for dep_context=non-requeueable deps ti=<TaskInstance: my_first_dag.task_1 scheduled__2025-01-01T06:51:30+00:00 [queued]>
[2025-02-06T12:23:24.375+0000] {taskinstance.py:2613} INFO - Dependencies all met for dep_context=requeueable deps ti=<TaskInstance: my_first_dag.task_1 scheduled__2025-01-01T06:51:30+00:00 [queued]>
[2025-02-06T12:23:24.377+0000] {taskinstance.py:2866} INFO - Starting attempt 1 of 1
[2025-02-06T12:23:24.445+0000] {taskinstance.py:2889} INFO - Executing <Task(PythonOperator): task_1> on 2025-01-01 06:51:30+00:00
[2025-02-06T12:23:24.455+0000] {standard_task_runner.py:72} INFO - Started process 817 to run task
[2025-02-06T12:23:24.457+0000] {standard_task_runner.py:104} INFO - Running: ['airflow', 'tasks', 'run', 'my_first_dag', 'task_1', 'scheduled__2025-01-01T06:51:30+00:00', '--job-id', '2462', '--raw', '--subdir', 'DAGS_FOLDER/first_dag.py', '--cfg-path', '/tmp/tmp4c7gsy3g']
[2025-02-06T12:23:24.458+0000] {standard_task_runner.py:105} INFO - Job 2462: Subtask task_1
[2025-02-06T12:23:24.580+0000] {task_command.py:467} INFO - Running <TaskInstance: my_first_dag.task_1 scheduled__2025-01-01T06:51:30+00:00 [running]> on host f59ce29465b4
[2025-02-06T12:23:24.634+0000] {standard_task_runner.py:124} ERROR - Failed to execute job 2462 for task task_1 ((sqlite3.OperationalError) disk I/O error
(Background on this error at: https://sqlalche.me/e/14/e3q8); 817)
Traceback (most recent call last):
  File "/opt/conda/lib/python3.12/site-packages/sqlalchemy/engine/base.py", line 1094, in _commit_impl
    self.engine.dialect.do_commit(self.connection)
  File "/opt/conda/lib/python3.12/site-packages/sqlalchemy/engine/default.py", line 686, in do_commit
    dbapi_connection.commit()
sqlite3.OperationalError: disk I/O error

The above exception was the direct cause of the following exception:

Traceback (most recent call last):
  File "/opt/conda/lib/python3.12/site-packages/airflow/task/task_runner/standard_task_runner.py", line 117, in _start_by_fork
    ret = args.func(args, dag=self.dag)
          ^^^^^^^^^^^^^^^^^^^^^^^^^^^^^
  File "/opt/conda/lib/python3.12/site-packages/airflow/cli/cli_config.py", line 49, in command
    return func(*args, **kwargs)
           ^^^^^^^^^^^^^^^^^^^^^
  File "/opt/conda/lib/python3.12/site-packages/airflow/utils/cli.py", line 116, in wrapper
    return f(*args, **kwargs)
           ^^^^^^^^^^^^^^^^^^
  File "/opt/conda/lib/python3.12/site-packages/airflow/cli/commands/task_command.py", line 483, in task_run
    task_return_code = _run_task_by_selected_method(args, _dag, ti)
                       ^^^^^^^^^^^^^^^^^^^^^^^^^^^^^^^^^^^^^^^^^^^^
  File "/opt/conda/lib/python3.12/site-packages/airflow/cli/commands/task_command.py", line 256, in _run_task_by_selected_method
    return _run_raw_task(args, ti)
           ^^^^^^^^^^^^^^^^^^^^^^^
  File "/opt/conda/lib/python3.12/site-packages/airflow/cli/commands/task_command.py", line 341, in _run_raw_task
    return ti._run_raw_task(
           ^^^^^^^^^^^^^^^^^
  File "/opt/conda/lib/python3.12/site-packages/airflow/utils/session.py", line 97, in wrapper
    return func(*args, session=session, **kwargs)
           ^^^^^^^^^^^^^^^^^^^^^^^^^^^^^^^^^^^^^^
  File "/opt/conda/lib/python3.12/site-packages/airflow/models/taskinstance.py", line 3005, in _run_raw_task
    return _run_raw_task(
           ^^^^^^^^^^^^^^
  File "/opt/conda/lib/python3.12/site-packages/airflow/models/taskinstance.py", line 249, in _run_raw_task
    TaskInstance.save_to_db(ti=ti, session=session)
  File "/opt/conda/lib/python3.12/site-packages/airflow/api_internal/internal_api_call.py", line 166, in wrapper
    return func(*args, **kwargs)
           ^^^^^^^^^^^^^^^^^^^^^
  File "/opt/conda/lib/python3.12/site-packages/airflow/utils/session.py", line 94, in wrapper
    return func(*args, **kwargs)
           ^^^^^^^^^^^^^^^^^^^^^
  File "/opt/conda/lib/python3.12/site-packages/airflow/models/taskinstance.py", line 3401, in save_to_db
    session.commit()
  File "/opt/conda/lib/python3.12/site-packages/sqlalchemy/orm/session.py", line 1454, in commit
    self._transaction.commit(_to_root=self.future)
  File "/opt/conda/lib/python3.12/site-packages/sqlalchemy/orm/session.py", line 839, in commit
    trans.commit()
  File "/opt/conda/lib/python3.12/site-packages/sqlalchemy/engine/base.py", line 2469, in commit
    self._do_commit()
  File "/opt/conda/lib/python3.12/site-packages/sqlalchemy/engine/base.py", line 2659, in _do_commit
    self._connection_commit_impl()
  File "/opt/conda/lib/python3.12/site-packages/sqlalchemy/engine/base.py", line 2630, in _connection_commit_impl
    self.connection._commit_impl()
  File "/opt/conda/lib/python3.12/site-packages/sqlalchemy/engine/base.py", line 1096, in _commit_impl
    self._handle_dbapi_exception(e, None, None, None, None)
  File "/opt/conda/lib/python3.12/site-packages/sqlalchemy/engine/base.py", line 2134, in _handle_dbapi_exception
    util.raise_(
  File "/opt/conda/lib/python3.12/site-packages/sqlalchemy/util/compat.py", line 211, in raise_
    raise exception
  File "/opt/conda/lib/python3.12/site-packages/sqlalchemy/engine/base.py", line 1094, in _commit_impl
    self.engine.dialect.do_commit(self.connection)
  File "/opt/conda/lib/python3.12/site-packages/sqlalchemy/engine/default.py", line 686, in do_commit
    dbapi_connection.commit()
sqlalchemy.exc.OperationalError: (sqlite3.OperationalError) disk I/O error
(Background on this error at: https://sqlalche.me/e/14/e3q8)
[2025-02-06T12:23:24.672+0000] {local_task_job_runner.py:266} INFO - Task exited with return code 1
[2025-02-06T12:23:24.719+0000] {taskinstance.py:3895} INFO - 0 downstream tasks scheduled from follow-on schedule check
[2025-02-06T12:23:24.721+0000] {local_task_job_runner.py:245} INFO - ::endgroup::
