[2025-02-06T13:23:12.703+0000] {local_task_job_runner.py:123} INFO - ::group::Pre task execution logs
[2025-02-06T13:23:12.730+0000] {taskinstance.py:2613} INFO - Dependencies all met for dep_context=non-requeueable deps ti=<TaskInstance: my_training_dag.task_insert_data scheduled__2025-01-01T01:50:30+00:00 [queued]>
[2025-02-06T13:23:12.751+0000] {taskinstance.py:2613} INFO - Dependencies all met for dep_context=requeueable deps ti=<TaskInstance: my_training_dag.task_insert_data scheduled__2025-01-01T01:50:30+00:00 [queued]>
[2025-02-06T13:23:12.752+0000] {taskinstance.py:2866} INFO - Starting attempt 1 of 1
[2025-02-06T13:23:12.934+0000] {taskinstance.py:2889} INFO - Executing <Task(PythonOperator): task_insert_data> on 2025-01-01 01:50:30+00:00
[2025-02-06T13:23:12.939+0000] {standard_task_runner.py:72} INFO - Started process 1792 to run task
[2025-02-06T13:23:12.941+0000] {standard_task_runner.py:104} INFO - Running: ['airflow', 'tasks', 'run', 'my_training_dag', 'task_insert_data', 'scheduled__2025-01-01T01:50:30+00:00', '--job-id', '3228', '--raw', '--subdir', 'DAGS_FOLDER/training_dag.py', '--cfg-path', '/tmp/tmpzyv1a2i1']
[2025-02-06T13:23:12.942+0000] {standard_task_runner.py:105} INFO - Job 3228: Subtask task_insert_data
[2025-02-06T13:23:13.029+0000] {task_command.py:467} INFO - Running <TaskInstance: my_training_dag.task_insert_data scheduled__2025-01-01T01:50:30+00:00 [running]> on host cbb1459a86bc
[2025-02-06T13:23:13.138+0000] {taskinstance.py:3132} INFO - Exporting env vars: AIRFLOW_CTX_DAG_OWNER='airflow' AIRFLOW_CTX_DAG_ID='my_training_dag' AIRFLOW_CTX_TASK_ID='task_insert_data' AIRFLOW_CTX_EXECUTION_DATE='2025-01-01T01:50:30+00:00' AIRFLOW_CTX_TRY_NUMBER='1' AIRFLOW_CTX_DAG_RUN_ID='scheduled__2025-01-01T01:50:30+00:00'
[2025-02-06T13:23:13.139+0000] {logging_mixin.py:190} INFO - Task instance is in running state
[2025-02-06T13:23:13.140+0000] {logging_mixin.py:190} INFO -  Previous state of the Task instance: queued
[2025-02-06T13:23:13.140+0000] {logging_mixin.py:190} INFO - Current task name:task_insert_data state:running start_date:2025-02-06 13:23:12.730908+00:00
[2025-02-06T13:23:13.141+0000] {logging_mixin.py:190} INFO - Dag name:my_training_dag and current dag run status:running
[2025-02-06T13:23:13.141+0000] {taskinstance.py:731} INFO - ::endgroup::
[2025-02-06T13:23:13.158+0000] {logging_mixin.py:190} INFO - Table : 'iris_data'  created succesfully
[2025-02-06T13:23:13.331+0000] {python.py:240} INFO - Done. Returned value was: None
[2025-02-06T13:23:13.343+0000] {taskinstance.py:340} INFO - ::group::Post task execution logs
[2025-02-06T13:23:13.343+0000] {taskinstance.py:352} INFO - Marking task as SUCCESS. dag_id=my_training_dag, task_id=task_insert_data, run_id=scheduled__2025-01-01T01:50:30+00:00, execution_date=20250101T015030, start_date=20250206T132312, end_date=20250206T132313
[2025-02-06T13:23:13.381+0000] {standard_task_runner.py:124} ERROR - Failed to execute job 3228 for task task_insert_data ((sqlite3.OperationalError) disk I/O error
(Background on this error at: https://sqlalche.me/e/14/e3q8); 1792)
Traceback (most recent call last):
  File "/opt/conda/lib/python3.12/site-packages/sqlalchemy/engine/base.py", line 1094, in _commit_impl
    self.engine.dialect.do_commit(self.connection)
  File "/opt/conda/lib/python3.12/site-packages/sqlalchemy/engine/default.py", line 686, in do_commit
    dbapi_connection.commit()
sqlite3.OperationalError: disk I/O error

The above exception was the direct cause of the following exception:

Traceback (most recent call last):
  File "/opt/conda/lib/python3.12/site-packages/airflow/task/task_runner/standard_task_runner.py", line 117, in _start_by_fork
    ret = args.func(args, dag=self.dag)
          ^^^^^^^^^^^^^^^^^^^^^^^^^^^^^
  File "/opt/conda/lib/python3.12/site-packages/airflow/cli/cli_config.py", line 49, in command
    return func(*args, **kwargs)
           ^^^^^^^^^^^^^^^^^^^^^
  File "/opt/conda/lib/python3.12/site-packages/airflow/utils/cli.py", line 116, in wrapper
    return f(*args, **kwargs)
           ^^^^^^^^^^^^^^^^^^
  File "/opt/conda/lib/python3.12/site-packages/airflow/cli/commands/task_command.py", line 483, in task_run
    task_return_code = _run_task_by_selected_method(args, _dag, ti)
                       ^^^^^^^^^^^^^^^^^^^^^^^^^^^^^^^^^^^^^^^^^^^^
  File "/opt/conda/lib/python3.12/site-packages/airflow/cli/commands/task_command.py", line 256, in _run_task_by_selected_method
    return _run_raw_task(args, ti)
           ^^^^^^^^^^^^^^^^^^^^^^^
  File "/opt/conda/lib/python3.12/site-packages/airflow/cli/commands/task_command.py", line 341, in _run_raw_task
    return ti._run_raw_task(
           ^^^^^^^^^^^^^^^^^
  File "/opt/conda/lib/python3.12/site-packages/airflow/utils/session.py", line 97, in wrapper
    return func(*args, session=session, **kwargs)
           ^^^^^^^^^^^^^^^^^^^^^^^^^^^^^^^^^^^^^^
  File "/opt/conda/lib/python3.12/site-packages/airflow/models/taskinstance.py", line 3005, in _run_raw_task
    return _run_raw_task(
           ^^^^^^^^^^^^^^
  File "/opt/conda/lib/python3.12/site-packages/airflow/models/taskinstance.py", line 365, in _run_raw_task
    TaskInstance.save_to_db(ti=ti, session=session)
  File "/opt/conda/lib/python3.12/site-packages/airflow/api_internal/internal_api_call.py", line 166, in wrapper
    return func(*args, **kwargs)
           ^^^^^^^^^^^^^^^^^^^^^
  File "/opt/conda/lib/python3.12/site-packages/airflow/utils/session.py", line 94, in wrapper
    return func(*args, **kwargs)
           ^^^^^^^^^^^^^^^^^^^^^
  File "/opt/conda/lib/python3.12/site-packages/airflow/models/taskinstance.py", line 3401, in save_to_db
    session.commit()
  File "/opt/conda/lib/python3.12/site-packages/sqlalchemy/orm/session.py", line 1454, in commit
    self._transaction.commit(_to_root=self.future)
  File "/opt/conda/lib/python3.12/site-packages/sqlalchemy/orm/session.py", line 839, in commit
    trans.commit()
  File "/opt/conda/lib/python3.12/site-packages/sqlalchemy/engine/base.py", line 2469, in commit
    self._do_commit()
  File "/opt/conda/lib/python3.12/site-packages/sqlalchemy/engine/base.py", line 2659, in _do_commit
    self._connection_commit_impl()
  File "/opt/conda/lib/python3.12/site-packages/sqlalchemy/engine/base.py", line 2630, in _connection_commit_impl
    self.connection._commit_impl()
  File "/opt/conda/lib/python3.12/site-packages/sqlalchemy/engine/base.py", line 1096, in _commit_impl
    self._handle_dbapi_exception(e, None, None, None, None)
  File "/opt/conda/lib/python3.12/site-packages/sqlalchemy/engine/base.py", line 2134, in _handle_dbapi_exception
    util.raise_(
  File "/opt/conda/lib/python3.12/site-packages/sqlalchemy/util/compat.py", line 211, in raise_
    raise exception
  File "/opt/conda/lib/python3.12/site-packages/sqlalchemy/engine/base.py", line 1094, in _commit_impl
    self.engine.dialect.do_commit(self.connection)
  File "/opt/conda/lib/python3.12/site-packages/sqlalchemy/engine/default.py", line 686, in do_commit
    dbapi_connection.commit()
sqlalchemy.exc.OperationalError: (sqlite3.OperationalError) disk I/O error
(Background on this error at: https://sqlalche.me/e/14/e3q8)
[2025-02-06T13:23:13.396+0000] {local_task_job_runner.py:266} INFO - Task exited with return code 1
[2025-02-06T13:23:13.434+0000] {taskinstance.py:3895} INFO - 0 downstream tasks scheduled from follow-on schedule check
[2025-02-06T13:23:13.435+0000] {local_task_job_runner.py:245} INFO - ::endgroup::
