[2025-02-06T13:04:57.002+0000] {local_task_job_runner.py:123} INFO - ::group::Pre task execution logs
[2025-02-06T13:04:57.023+0000] {taskinstance.py:2613} INFO - Dependencies all met for dep_context=non-requeueable deps ti=<TaskInstance: my_first_dag.task_random_choice scheduled__2025-01-01T07:34:30+00:00 [queued]>
[2025-02-06T13:04:57.055+0000] {taskinstance.py:2613} INFO - Dependencies all met for dep_context=requeueable deps ti=<TaskInstance: my_first_dag.task_random_choice scheduled__2025-01-01T07:34:30+00:00 [queued]>
[2025-02-06T13:04:57.057+0000] {taskinstance.py:2866} INFO - Starting attempt 1 of 1
[2025-02-06T13:04:57.195+0000] {taskinstance.py:2889} INFO - Executing <Task(BranchPythonOperator): task_random_choice> on 2025-01-01 07:34:30+00:00
[2025-02-06T13:04:57.199+0000] {standard_task_runner.py:72} INFO - Started process 2262 to run task
[2025-02-06T13:04:57.201+0000] {standard_task_runner.py:104} INFO - Running: ['airflow', 'tasks', 'run', 'my_first_dag', 'task_random_choice', 'scheduled__2025-01-01T07:34:30+00:00', '--job-id', '3123', '--raw', '--subdir', 'DAGS_FOLDER/first_dag.py', '--cfg-path', '/tmp/tmpanz_ptl1']
[2025-02-06T13:04:57.202+0000] {standard_task_runner.py:105} INFO - Job 3123: Subtask task_random_choice
[2025-02-06T13:04:57.289+0000] {task_command.py:467} INFO - Running <TaskInstance: my_first_dag.task_random_choice scheduled__2025-01-01T07:34:30+00:00 [running]> on host 843ef7911ffd
[2025-02-06T13:04:57.396+0000] {taskinstance.py:3132} INFO - Exporting env vars: AIRFLOW_CTX_DAG_OWNER='airflow' AIRFLOW_CTX_DAG_ID='my_first_dag' AIRFLOW_CTX_TASK_ID='task_random_choice' AIRFLOW_CTX_EXECUTION_DATE='2025-01-01T07:34:30+00:00' AIRFLOW_CTX_TRY_NUMBER='1' AIRFLOW_CTX_DAG_RUN_ID='scheduled__2025-01-01T07:34:30+00:00'
[2025-02-06T13:04:57.398+0000] {logging_mixin.py:190} INFO - Task instance is in running state
[2025-02-06T13:04:57.399+0000] {logging_mixin.py:190} INFO -  Previous state of the Task instance: queued
[2025-02-06T13:04:57.399+0000] {logging_mixin.py:190} INFO - Current task name:task_random_choice state:running start_date:2025-02-06 13:04:57.023760+00:00
[2025-02-06T13:04:57.400+0000] {logging_mixin.py:190} INFO - Dag name:my_first_dag and current dag run status:running
[2025-02-06T13:04:57.400+0000] {taskinstance.py:731} INFO - ::endgroup::
[2025-02-06T13:04:57.400+0000] {baseoperator.py:421} WARNING - BranchPythonOperator.execute cannot be called outside TaskInstance!
[2025-02-06T13:04:57.401+0000] {python.py:240} INFO - Done. Returned value was: task_2
[2025-02-06T13:04:57.401+0000] {branch.py:38} INFO - Branch into task_2
[2025-02-06T13:04:57.402+0000] {skipmixin.py:230} INFO - Following branch ('task_2',)
[2025-02-06T13:04:57.413+0000] {skipmixin.py:278} INFO - Skipping tasks [('task_1', -1)]
[2025-02-06T13:04:57.488+0000] {taskinstance.py:340} INFO - ::group::Post task execution logs
[2025-02-06T13:04:57.489+0000] {taskinstance.py:352} INFO - Marking task as SUCCESS. dag_id=my_first_dag, task_id=task_random_choice, run_id=scheduled__2025-01-01T07:34:30+00:00, execution_date=20250101T073430, start_date=20250206T130457, end_date=20250206T130457
[2025-02-06T13:04:57.531+0000] {standard_task_runner.py:124} ERROR - Failed to execute job 3123 for task task_random_choice ((sqlite3.OperationalError) disk I/O error
(Background on this error at: https://sqlalche.me/e/14/e3q8); 2262)
Traceback (most recent call last):
  File "/opt/conda/lib/python3.12/site-packages/sqlalchemy/engine/base.py", line 1094, in _commit_impl
    self.engine.dialect.do_commit(self.connection)
  File "/opt/conda/lib/python3.12/site-packages/sqlalchemy/engine/default.py", line 686, in do_commit
    dbapi_connection.commit()
sqlite3.OperationalError: disk I/O error

The above exception was the direct cause of the following exception:

Traceback (most recent call last):
  File "/opt/conda/lib/python3.12/site-packages/airflow/task/task_runner/standard_task_runner.py", line 117, in _start_by_fork
    ret = args.func(args, dag=self.dag)
          ^^^^^^^^^^^^^^^^^^^^^^^^^^^^^
  File "/opt/conda/lib/python3.12/site-packages/airflow/cli/cli_config.py", line 49, in command
    return func(*args, **kwargs)
           ^^^^^^^^^^^^^^^^^^^^^
  File "/opt/conda/lib/python3.12/site-packages/airflow/utils/cli.py", line 116, in wrapper
    return f(*args, **kwargs)
           ^^^^^^^^^^^^^^^^^^
  File "/opt/conda/lib/python3.12/site-packages/airflow/cli/commands/task_command.py", line 483, in task_run
    task_return_code = _run_task_by_selected_method(args, _dag, ti)
                       ^^^^^^^^^^^^^^^^^^^^^^^^^^^^^^^^^^^^^^^^^^^^
  File "/opt/conda/lib/python3.12/site-packages/airflow/cli/commands/task_command.py", line 256, in _run_task_by_selected_method
    return _run_raw_task(args, ti)
           ^^^^^^^^^^^^^^^^^^^^^^^
  File "/opt/conda/lib/python3.12/site-packages/airflow/cli/commands/task_command.py", line 341, in _run_raw_task
    return ti._run_raw_task(
           ^^^^^^^^^^^^^^^^^
  File "/opt/conda/lib/python3.12/site-packages/airflow/utils/session.py", line 97, in wrapper
    return func(*args, session=session, **kwargs)
           ^^^^^^^^^^^^^^^^^^^^^^^^^^^^^^^^^^^^^^
  File "/opt/conda/lib/python3.12/site-packages/airflow/models/taskinstance.py", line 3005, in _run_raw_task
    return _run_raw_task(
           ^^^^^^^^^^^^^^
  File "/opt/conda/lib/python3.12/site-packages/airflow/models/taskinstance.py", line 365, in _run_raw_task
    TaskInstance.save_to_db(ti=ti, session=session)
  File "/opt/conda/lib/python3.12/site-packages/airflow/api_internal/internal_api_call.py", line 166, in wrapper
    return func(*args, **kwargs)
           ^^^^^^^^^^^^^^^^^^^^^
  File "/opt/conda/lib/python3.12/site-packages/airflow/utils/session.py", line 94, in wrapper
    return func(*args, **kwargs)
           ^^^^^^^^^^^^^^^^^^^^^
  File "/opt/conda/lib/python3.12/site-packages/airflow/models/taskinstance.py", line 3401, in save_to_db
    session.commit()
  File "/opt/conda/lib/python3.12/site-packages/sqlalchemy/orm/session.py", line 1454, in commit
    self._transaction.commit(_to_root=self.future)
  File "/opt/conda/lib/python3.12/site-packages/sqlalchemy/orm/session.py", line 839, in commit
    trans.commit()
  File "/opt/conda/lib/python3.12/site-packages/sqlalchemy/engine/base.py", line 2469, in commit
    self._do_commit()
  File "/opt/conda/lib/python3.12/site-packages/sqlalchemy/engine/base.py", line 2659, in _do_commit
    self._connection_commit_impl()
  File "/opt/conda/lib/python3.12/site-packages/sqlalchemy/engine/base.py", line 2630, in _connection_commit_impl
    self.connection._commit_impl()
  File "/opt/conda/lib/python3.12/site-packages/sqlalchemy/engine/base.py", line 1096, in _commit_impl
    self._handle_dbapi_exception(e, None, None, None, None)
  File "/opt/conda/lib/python3.12/site-packages/sqlalchemy/engine/base.py", line 2134, in _handle_dbapi_exception
    util.raise_(
  File "/opt/conda/lib/python3.12/site-packages/sqlalchemy/util/compat.py", line 211, in raise_
    raise exception
  File "/opt/conda/lib/python3.12/site-packages/sqlalchemy/engine/base.py", line 1094, in _commit_impl
    self.engine.dialect.do_commit(self.connection)
  File "/opt/conda/lib/python3.12/site-packages/sqlalchemy/engine/default.py", line 686, in do_commit
    dbapi_connection.commit()
sqlalchemy.exc.OperationalError: (sqlite3.OperationalError) disk I/O error
(Background on this error at: https://sqlalche.me/e/14/e3q8)
[2025-02-06T13:04:57.576+0000] {local_task_job_runner.py:266} INFO - Task exited with return code 1
[2025-02-06T13:04:57.623+0000] {taskinstance.py:3895} INFO - 0 downstream tasks scheduled from follow-on schedule check
[2025-02-06T13:04:57.626+0000] {local_task_job_runner.py:245} INFO - ::endgroup::
