[2025-02-06T11:47:30.844+0000] {local_task_job_runner.py:123} INFO - ::group::Pre task execution logs
[2025-02-06T11:47:30.930+0000] {taskinstance.py:2613} INFO - Dependencies all met for dep_context=non-requeueable deps ti=<TaskInstance: my_first_dag.task_2 scheduled__2025-01-01T06:23:30+00:00 [queued]>
[2025-02-06T11:47:31.023+0000] {taskinstance.py:2613} INFO - Dependencies all met for dep_context=requeueable deps ti=<TaskInstance: my_first_dag.task_2 scheduled__2025-01-01T06:23:30+00:00 [queued]>
[2025-02-06T11:47:31.026+0000] {taskinstance.py:2866} INFO - Starting attempt 1 of 1
[2025-02-06T11:47:31.129+0000] {taskinstance.py:2889} INFO - Executing <Task(PythonOperator): task_2> on 2025-01-01 06:23:30+00:00
[2025-02-06T11:47:31.142+0000] {standard_task_runner.py:72} INFO - Started process 1962 to run task
[2025-02-06T11:47:31.149+0000] {standard_task_runner.py:104} INFO - Running: ['airflow', 'tasks', 'run', 'my_first_dag', 'task_2', 'scheduled__2025-01-01T06:23:30+00:00', '--job-id', '2151', '--raw', '--subdir', 'DAGS_FOLDER/first_dag.py', '--cfg-path', '/tmp/tmpg6675aqk']
[2025-02-06T11:47:31.152+0000] {standard_task_runner.py:105} INFO - Job 2151: Subtask task_2
[2025-02-06T11:47:31.389+0000] {task_command.py:467} INFO - Running <TaskInstance: my_first_dag.task_2 scheduled__2025-01-01T06:23:30+00:00 [running]> on host 7e1f175e93b1
[2025-02-06T11:47:31.905+0000] {taskinstance.py:3132} INFO - Exporting env vars: AIRFLOW_CTX_DAG_OWNER='airflow' AIRFLOW_CTX_DAG_ID='my_first_dag' AIRFLOW_CTX_TASK_ID='task_2' AIRFLOW_CTX_EXECUTION_DATE='2025-01-01T06:23:30+00:00' AIRFLOW_CTX_TRY_NUMBER='1' AIRFLOW_CTX_DAG_RUN_ID='scheduled__2025-01-01T06:23:30+00:00'
[2025-02-06T11:47:31.909+0000] {logging_mixin.py:190} INFO - Task instance is in running state
[2025-02-06T11:47:31.912+0000] {logging_mixin.py:190} INFO -  Previous state of the Task instance: queued
[2025-02-06T11:47:31.914+0000] {logging_mixin.py:190} INFO - Current task name:task_2 state:running start_date:2025-02-06 11:47:30.931685+00:00
[2025-02-06T11:47:31.916+0000] {logging_mixin.py:190} INFO - Dag name:my_first_dag and current dag run status:running
[2025-02-06T11:47:31.917+0000] {taskinstance.py:731} INFO - ::endgroup::
[2025-02-06T11:47:31.998+0000] {logging_mixin.py:190} INFO - Hello John 653 API_KEY
[2025-02-06T11:47:32.000+0000] {python.py:240} INFO - Done. Returned value was: 653
[2025-02-06T11:47:32.087+0000] {taskinstance.py:3311} ERROR - Task failed with exception
Traceback (most recent call last):
  File "/opt/conda/lib/python3.12/site-packages/sqlalchemy/engine/base.py", line 1094, in _commit_impl
    self.engine.dialect.do_commit(self.connection)
  File "/opt/conda/lib/python3.12/site-packages/sqlalchemy/engine/default.py", line 686, in do_commit
    dbapi_connection.commit()
sqlite3.OperationalError: disk I/O error

The above exception was the direct cause of the following exception:

Traceback (most recent call last):
  File "/opt/conda/lib/python3.12/site-packages/airflow/models/taskinstance.py", line 769, in _execute_task
    with cm as session_or_null:
         ^^
  File "/opt/conda/lib/python3.12/contextlib.py", line 144, in __exit__
    next(self.gen)
  File "/opt/conda/lib/python3.12/site-packages/airflow/utils/session.py", line 57, in create_session
    session.commit()
  File "/opt/conda/lib/python3.12/site-packages/sqlalchemy/orm/session.py", line 1454, in commit
    self._transaction.commit(_to_root=self.future)
  File "/opt/conda/lib/python3.12/site-packages/sqlalchemy/orm/session.py", line 839, in commit
    trans.commit()
  File "/opt/conda/lib/python3.12/site-packages/sqlalchemy/engine/base.py", line 2469, in commit
    self._do_commit()
  File "/opt/conda/lib/python3.12/site-packages/sqlalchemy/engine/base.py", line 2659, in _do_commit
    self._connection_commit_impl()
  File "/opt/conda/lib/python3.12/site-packages/sqlalchemy/engine/base.py", line 2630, in _connection_commit_impl
    self.connection._commit_impl()
  File "/opt/conda/lib/python3.12/site-packages/sqlalchemy/engine/base.py", line 1096, in _commit_impl
    self._handle_dbapi_exception(e, None, None, None, None)
  File "/opt/conda/lib/python3.12/site-packages/sqlalchemy/engine/base.py", line 2134, in _handle_dbapi_exception
    util.raise_(
  File "/opt/conda/lib/python3.12/site-packages/sqlalchemy/util/compat.py", line 211, in raise_
    raise exception
  File "/opt/conda/lib/python3.12/site-packages/sqlalchemy/engine/base.py", line 1094, in _commit_impl
    self.engine.dialect.do_commit(self.connection)
  File "/opt/conda/lib/python3.12/site-packages/sqlalchemy/engine/default.py", line 686, in do_commit
    dbapi_connection.commit()
sqlalchemy.exc.OperationalError: (sqlite3.OperationalError) disk I/O error
(Background on this error at: https://sqlalche.me/e/14/e3q8)
[2025-02-06T11:47:32.477+0000] {logging_mixin.py:190} INFO - Task instance in failure state
[2025-02-06T11:47:32.478+0000] {logging_mixin.py:190} INFO - Task start:2025-02-06 11:47:30.931685+00:00 end:2025-02-06 11:47:32.475347+00:00 duration:1.543662
[2025-02-06T11:47:32.480+0000] {logging_mixin.py:190} INFO - Task:<Task(PythonOperator): task_2> dag:<DAG: my_first_dag> dagrun:<DagRun my_first_dag @ 2025-01-01 06:23:30+00:00: scheduled__2025-01-01T06:23:30+00:00, state:running, queued_at: 2025-02-06 11:47:01.080059+00:00. externally triggered: False>
[2025-02-06T11:47:32.482+0000] {logging_mixin.py:190} INFO - Failure caused by (sqlite3.OperationalError) disk I/O error
(Background on this error at: https://sqlalche.me/e/14/e3q8)
[2025-02-06T11:47:32.486+0000] {taskinstance.py:1225} INFO - Marking task as FAILED. dag_id=my_first_dag, task_id=task_2, run_id=scheduled__2025-01-01T06:23:30+00:00, execution_date=20250101T062330, start_date=20250206T114730, end_date=20250206T114732
[2025-02-06T11:47:32.645+0000] {taskinstance.py:340} INFO - ::group::Post task execution logs
[2025-02-06T11:47:32.647+0000] {standard_task_runner.py:124} ERROR - Failed to execute job 2151 for task task_2 ((sqlite3.OperationalError) disk I/O error
(Background on this error at: https://sqlalche.me/e/14/e3q8); 1962)
Traceback (most recent call last):
  File "/opt/conda/lib/python3.12/site-packages/sqlalchemy/engine/base.py", line 1094, in _commit_impl
    self.engine.dialect.do_commit(self.connection)
  File "/opt/conda/lib/python3.12/site-packages/sqlalchemy/engine/default.py", line 686, in do_commit
    dbapi_connection.commit()
sqlite3.OperationalError: disk I/O error

The above exception was the direct cause of the following exception:

Traceback (most recent call last):
  File "/opt/conda/lib/python3.12/site-packages/airflow/task/task_runner/standard_task_runner.py", line 117, in _start_by_fork
    ret = args.func(args, dag=self.dag)
          ^^^^^^^^^^^^^^^^^^^^^^^^^^^^^
  File "/opt/conda/lib/python3.12/site-packages/airflow/cli/cli_config.py", line 49, in command
    return func(*args, **kwargs)
           ^^^^^^^^^^^^^^^^^^^^^
  File "/opt/conda/lib/python3.12/site-packages/airflow/utils/cli.py", line 116, in wrapper
    return f(*args, **kwargs)
           ^^^^^^^^^^^^^^^^^^
  File "/opt/conda/lib/python3.12/site-packages/airflow/cli/commands/task_command.py", line 483, in task_run
    task_return_code = _run_task_by_selected_method(args, _dag, ti)
                       ^^^^^^^^^^^^^^^^^^^^^^^^^^^^^^^^^^^^^^^^^^^^
  File "/opt/conda/lib/python3.12/site-packages/airflow/cli/commands/task_command.py", line 256, in _run_task_by_selected_method
    return _run_raw_task(args, ti)
           ^^^^^^^^^^^^^^^^^^^^^^^
  File "/opt/conda/lib/python3.12/site-packages/airflow/cli/commands/task_command.py", line 341, in _run_raw_task
    return ti._run_raw_task(
           ^^^^^^^^^^^^^^^^^
  File "/opt/conda/lib/python3.12/site-packages/airflow/utils/session.py", line 97, in wrapper
    return func(*args, session=session, **kwargs)
           ^^^^^^^^^^^^^^^^^^^^^^^^^^^^^^^^^^^^^^
  File "/opt/conda/lib/python3.12/site-packages/airflow/models/taskinstance.py", line 3005, in _run_raw_task
    return _run_raw_task(
           ^^^^^^^^^^^^^^
  File "/opt/conda/lib/python3.12/site-packages/airflow/models/taskinstance.py", line 273, in _run_raw_task
    TaskInstance._execute_task_with_callbacks(
  File "/opt/conda/lib/python3.12/site-packages/airflow/models/taskinstance.py", line 3159, in _execute_task_with_callbacks
    result = self._execute_task(context, task_orig)
             ^^^^^^^^^^^^^^^^^^^^^^^^^^^^^^^^^^^^^^
  File "/opt/conda/lib/python3.12/site-packages/airflow/models/taskinstance.py", line 3183, in _execute_task
    return _execute_task(self, context, task_orig)
           ^^^^^^^^^^^^^^^^^^^^^^^^^^^^^^^^^^^^^^^
  File "/opt/conda/lib/python3.12/site-packages/airflow/models/taskinstance.py", line 769, in _execute_task
    with cm as session_or_null:
         ^^
  File "/opt/conda/lib/python3.12/contextlib.py", line 144, in __exit__
    next(self.gen)
  File "/opt/conda/lib/python3.12/site-packages/airflow/utils/session.py", line 57, in create_session
    session.commit()
  File "/opt/conda/lib/python3.12/site-packages/sqlalchemy/orm/session.py", line 1454, in commit
    self._transaction.commit(_to_root=self.future)
  File "/opt/conda/lib/python3.12/site-packages/sqlalchemy/orm/session.py", line 839, in commit
    trans.commit()
  File "/opt/conda/lib/python3.12/site-packages/sqlalchemy/engine/base.py", line 2469, in commit
    self._do_commit()
  File "/opt/conda/lib/python3.12/site-packages/sqlalchemy/engine/base.py", line 2659, in _do_commit
    self._connection_commit_impl()
  File "/opt/conda/lib/python3.12/site-packages/sqlalchemy/engine/base.py", line 2630, in _connection_commit_impl
    self.connection._commit_impl()
  File "/opt/conda/lib/python3.12/site-packages/sqlalchemy/engine/base.py", line 1096, in _commit_impl
    self._handle_dbapi_exception(e, None, None, None, None)
  File "/opt/conda/lib/python3.12/site-packages/sqlalchemy/engine/base.py", line 2134, in _handle_dbapi_exception
    util.raise_(
  File "/opt/conda/lib/python3.12/site-packages/sqlalchemy/util/compat.py", line 211, in raise_
    raise exception
  File "/opt/conda/lib/python3.12/site-packages/sqlalchemy/engine/base.py", line 1094, in _commit_impl
    self.engine.dialect.do_commit(self.connection)
  File "/opt/conda/lib/python3.12/site-packages/sqlalchemy/engine/default.py", line 686, in do_commit
    dbapi_connection.commit()
sqlalchemy.exc.OperationalError: (sqlite3.OperationalError) disk I/O error
(Background on this error at: https://sqlalche.me/e/14/e3q8)
[2025-02-06T11:47:32.697+0000] {local_task_job_runner.py:266} INFO - Task exited with return code 1
[2025-02-06T11:47:32.842+0000] {taskinstance.py:3895} INFO - 0 downstream tasks scheduled from follow-on schedule check
[2025-02-06T11:47:32.941+0000] {local_task_job_runner.py:245} INFO - ::endgroup::
