[2025-02-06T12:38:52.463+0000] {local_task_job_runner.py:123} INFO - ::group::Pre task execution logs
[2025-02-06T12:38:52.481+0000] {taskinstance.py:2613} INFO - Dependencies all met for dep_context=non-requeueable deps ti=<TaskInstance: my_training_dag.task_load_data scheduled__2025-01-01T00:55:00+00:00 [queued]>
[2025-02-06T12:38:52.493+0000] {taskinstance.py:2613} INFO - Dependencies all met for dep_context=requeueable deps ti=<TaskInstance: my_training_dag.task_load_data scheduled__2025-01-01T00:55:00+00:00 [queued]>
[2025-02-06T12:38:52.495+0000] {taskinstance.py:2866} INFO - Starting attempt 1 of 1
[2025-02-06T12:38:52.529+0000] {taskinstance.py:2889} INFO - Executing <Task(PythonOperator): task_load_data> on 2025-01-01 00:55:00+00:00
[2025-02-06T12:38:52.534+0000] {standard_task_runner.py:72} INFO - Started process 8448 to run task
[2025-02-06T12:38:52.536+0000] {standard_task_runner.py:104} INFO - Running: ['airflow', 'tasks', 'run', 'my_training_dag', 'task_load_data', 'scheduled__2025-01-01T00:55:00+00:00', '--job-id', '2758', '--raw', '--subdir', 'DAGS_FOLDER/training_dag.py', '--cfg-path', '/tmp/tmppp_8ib6k']
[2025-02-06T12:38:52.541+0000] {standard_task_runner.py:105} INFO - Job 2758: Subtask task_load_data
[2025-02-06T12:38:52.625+0000] {task_command.py:467} INFO - Running <TaskInstance: my_training_dag.task_load_data scheduled__2025-01-01T00:55:00+00:00 [running]> on host f59ce29465b4
[2025-02-06T12:38:52.740+0000] {taskinstance.py:3132} INFO - Exporting env vars: AIRFLOW_CTX_DAG_OWNER='airflow' AIRFLOW_CTX_DAG_ID='my_training_dag' AIRFLOW_CTX_TASK_ID='task_load_data' AIRFLOW_CTX_EXECUTION_DATE='2025-01-01T00:55:00+00:00' AIRFLOW_CTX_TRY_NUMBER='1' AIRFLOW_CTX_DAG_RUN_ID='scheduled__2025-01-01T00:55:00+00:00'
[2025-02-06T12:38:52.742+0000] {logging_mixin.py:190} INFO - Task instance is in running state
[2025-02-06T12:38:52.749+0000] {logging_mixin.py:190} INFO -  Previous state of the Task instance: queued
[2025-02-06T12:38:52.750+0000] {logging_mixin.py:190} INFO - Current task name:task_load_data state:running start_date:2025-02-06 12:38:52.482043+00:00
[2025-02-06T12:38:52.751+0000] {logging_mixin.py:190} INFO - Dag name:my_training_dag and current dag run status:running
[2025-02-06T12:38:52.751+0000] {taskinstance.py:731} INFO - ::endgroup::
[2025-02-06T12:38:52.754+0000] {taskinstance.py:3311} ERROR - Task failed with exception
Traceback (most recent call last):
  File "/opt/conda/lib/python3.12/site-packages/airflow/models/taskinstance.py", line 767, in _execute_task
    result = _execute_callable(context=context, **execute_callable_kwargs)
             ^^^^^^^^^^^^^^^^^^^^^^^^^^^^^^^^^^^^^^^^^^^^^^^^^^^^^^^^^^^^^
  File "/opt/conda/lib/python3.12/site-packages/airflow/models/taskinstance.py", line 733, in _execute_callable
    return ExecutionCallableRunner(
           ^^^^^^^^^^^^^^^^^^^^^^^^
  File "/opt/conda/lib/python3.12/site-packages/airflow/utils/operator_helpers.py", line 252, in run
    return self.func(*args, **kwargs)
           ^^^^^^^^^^^^^^^^^^^^^^^^^^
  File "/opt/conda/lib/python3.12/site-packages/airflow/models/baseoperator.py", line 422, in wrapper
    return func(self, *args, **kwargs)
           ^^^^^^^^^^^^^^^^^^^^^^^^^^^
  File "/opt/conda/lib/python3.12/site-packages/airflow/operators/python.py", line 238, in execute
    return_value = self.execute_callable()
                   ^^^^^^^^^^^^^^^^^^^^^^^
  File "/opt/conda/lib/python3.12/site-packages/airflow/operators/python.py", line 256, in execute_callable
    return runner.run(*self.op_args, **self.op_kwargs)
           ^^^^^^^^^^^^^^^^^^^^^^^^^^^^^^^^^^^^^^^^^^^
  File "/opt/conda/lib/python3.12/site-packages/airflow/utils/operator_helpers.py", line 252, in run
    return self.func(*args, **kwargs)
           ^^^^^^^^^^^^^^^^^^^^^^^^^^
  File "/root/airflow/dags/training_dag.py", line 12, in load_data
    df = pd.DataFrame(df.data, columns=['sepal_length', 'sepal_width', 'petal_length', 'petal_width'])
                      ^^
UnboundLocalError: cannot access local variable 'df' where it is not associated with a value
[2025-02-06T12:38:52.769+0000] {logging_mixin.py:190} INFO - Task instance in failure state
[2025-02-06T12:38:52.770+0000] {logging_mixin.py:190} INFO - Task start:2025-02-06 12:38:52.482043+00:00 end:2025-02-06 12:38:52.769468+00:00 duration:0.287425
[2025-02-06T12:38:52.771+0000] {logging_mixin.py:190} INFO - Task:<Task(PythonOperator): task_load_data> dag:<DAG: my_training_dag> dagrun:<DagRun my_training_dag @ 2025-01-01 00:55:00+00:00: scheduled__2025-01-01T00:55:00+00:00, state:running, queued_at: 2025-02-06 12:38:50.193423+00:00. externally triggered: False>
[2025-02-06T12:38:52.771+0000] {logging_mixin.py:190} INFO - Failure caused by cannot access local variable 'df' where it is not associated with a value
[2025-02-06T12:38:52.771+0000] {taskinstance.py:1225} INFO - Marking task as FAILED. dag_id=my_training_dag, task_id=task_load_data, run_id=scheduled__2025-01-01T00:55:00+00:00, execution_date=20250101T005500, start_date=20250206T123852, end_date=20250206T123852
[2025-02-06T12:38:52.922+0000] {taskinstance.py:340} INFO - ::group::Post task execution logs
[2025-02-06T12:38:52.923+0000] {standard_task_runner.py:124} ERROR - Failed to execute job 2758 for task task_load_data (cannot access local variable 'df' where it is not associated with a value; 8448)
Traceback (most recent call last):
  File "/opt/conda/lib/python3.12/site-packages/airflow/task/task_runner/standard_task_runner.py", line 117, in _start_by_fork
    ret = args.func(args, dag=self.dag)
          ^^^^^^^^^^^^^^^^^^^^^^^^^^^^^
  File "/opt/conda/lib/python3.12/site-packages/airflow/cli/cli_config.py", line 49, in command
    return func(*args, **kwargs)
           ^^^^^^^^^^^^^^^^^^^^^
  File "/opt/conda/lib/python3.12/site-packages/airflow/utils/cli.py", line 116, in wrapper
    return f(*args, **kwargs)
           ^^^^^^^^^^^^^^^^^^
  File "/opt/conda/lib/python3.12/site-packages/airflow/cli/commands/task_command.py", line 483, in task_run
    task_return_code = _run_task_by_selected_method(args, _dag, ti)
                       ^^^^^^^^^^^^^^^^^^^^^^^^^^^^^^^^^^^^^^^^^^^^
  File "/opt/conda/lib/python3.12/site-packages/airflow/cli/commands/task_command.py", line 256, in _run_task_by_selected_method
    return _run_raw_task(args, ti)
           ^^^^^^^^^^^^^^^^^^^^^^^
  File "/opt/conda/lib/python3.12/site-packages/airflow/cli/commands/task_command.py", line 341, in _run_raw_task
    return ti._run_raw_task(
           ^^^^^^^^^^^^^^^^^
  File "/opt/conda/lib/python3.12/site-packages/airflow/utils/session.py", line 97, in wrapper
    return func(*args, session=session, **kwargs)
           ^^^^^^^^^^^^^^^^^^^^^^^^^^^^^^^^^^^^^^
  File "/opt/conda/lib/python3.12/site-packages/airflow/models/taskinstance.py", line 3005, in _run_raw_task
    return _run_raw_task(
           ^^^^^^^^^^^^^^
  File "/opt/conda/lib/python3.12/site-packages/airflow/models/taskinstance.py", line 273, in _run_raw_task
    TaskInstance._execute_task_with_callbacks(
  File "/opt/conda/lib/python3.12/site-packages/airflow/models/taskinstance.py", line 3159, in _execute_task_with_callbacks
    result = self._execute_task(context, task_orig)
             ^^^^^^^^^^^^^^^^^^^^^^^^^^^^^^^^^^^^^^
  File "/opt/conda/lib/python3.12/site-packages/airflow/models/taskinstance.py", line 3183, in _execute_task
    return _execute_task(self, context, task_orig)
           ^^^^^^^^^^^^^^^^^^^^^^^^^^^^^^^^^^^^^^^
  File "/opt/conda/lib/python3.12/site-packages/airflow/models/taskinstance.py", line 767, in _execute_task
    result = _execute_callable(context=context, **execute_callable_kwargs)
             ^^^^^^^^^^^^^^^^^^^^^^^^^^^^^^^^^^^^^^^^^^^^^^^^^^^^^^^^^^^^^
  File "/opt/conda/lib/python3.12/site-packages/airflow/models/taskinstance.py", line 733, in _execute_callable
    return ExecutionCallableRunner(
           ^^^^^^^^^^^^^^^^^^^^^^^^
  File "/opt/conda/lib/python3.12/site-packages/airflow/utils/operator_helpers.py", line 252, in run
    return self.func(*args, **kwargs)
           ^^^^^^^^^^^^^^^^^^^^^^^^^^
  File "/opt/conda/lib/python3.12/site-packages/airflow/models/baseoperator.py", line 422, in wrapper
    return func(self, *args, **kwargs)
           ^^^^^^^^^^^^^^^^^^^^^^^^^^^
  File "/opt/conda/lib/python3.12/site-packages/airflow/operators/python.py", line 238, in execute
    return_value = self.execute_callable()
                   ^^^^^^^^^^^^^^^^^^^^^^^
  File "/opt/conda/lib/python3.12/site-packages/airflow/operators/python.py", line 256, in execute_callable
    return runner.run(*self.op_args, **self.op_kwargs)
           ^^^^^^^^^^^^^^^^^^^^^^^^^^^^^^^^^^^^^^^^^^^
  File "/opt/conda/lib/python3.12/site-packages/airflow/utils/operator_helpers.py", line 252, in run
    return self.func(*args, **kwargs)
           ^^^^^^^^^^^^^^^^^^^^^^^^^^
  File "/root/airflow/dags/training_dag.py", line 12, in load_data
    df = pd.DataFrame(df.data, columns=['sepal_length', 'sepal_width', 'petal_length', 'petal_width'])
                      ^^
UnboundLocalError: cannot access local variable 'df' where it is not associated with a value
[2025-02-06T12:38:52.955+0000] {local_task_job_runner.py:266} INFO - Task exited with return code 1
[2025-02-06T12:38:52.976+0000] {taskinstance.py:3895} INFO - 0 downstream tasks scheduled from follow-on schedule check
[2025-02-06T12:38:53.017+0000] {local_task_job_runner.py:245} INFO - ::endgroup::
